2015-06-02 10:12:15 main.py[line:72] ERROR 数据写入失败:not all arguments converted during string formatting
2015-06-02 10:12:28 main.py[line:72] ERROR 数据写入失败:not all arguments converted during string formatting
2015-06-02 10:13:30 main.py[line:72] ERROR 数据写入失败:not all arguments converted during string formatting
2015-06-02 10:13:31 main.py[line:72] ERROR 数据写入失败:not all arguments converted during string formatting
2015-06-02 10:13:31 main.py[line:72] ERROR 数据写入失败:not all arguments converted during string formatting
2015-06-02 10:14:32 main.py[line:72] ERROR 数据写入失败:not all arguments converted during string formatting
2015-06-02 10:14:58 main.py[line:72] ERROR 数据写入失败:not all arguments converted during string formatting
2015-06-02 10:17:24 main.py[line:72] ERROR 数据写入失败:not all arguments converted during string formatting
2015-06-02 10:17:41 main.py[line:72] ERROR 数据写入失败:not all arguments converted during string formatting
2015-06-02 10:17:55 main.py[line:72] ERROR 数据写入失败:not all arguments converted during string formatting
2015-06-02 10:29:45 main.py[line:72] ERROR 数据写入失败:not all arguments converted during string formatting
2015-06-02 10:29:46 main.py[line:72] ERROR 数据写入失败:not all arguments converted during string formatting
2015-06-02 10:29:46 main.py[line:72] ERROR 数据写入失败:not all arguments converted during string formatting
2015-06-02 10:29:46 main.py[line:72] ERROR 数据写入失败:not all arguments converted during string formatting
2015-06-02 10:29:47 main.py[line:72] ERROR 数据写入失败:not all arguments converted during string formatting
2015-06-02 10:29:55 main.py[line:72] ERROR 数据写入失败:not all arguments converted during string formatting
2015-06-02 10:30:12 main.py[line:72] ERROR 数据写入失败:not all arguments converted during string formatting
2015-06-02 10:30:48 main.py[line:72] ERROR 数据写入失败:not all arguments converted during string formatting
2015-06-02 10:31:50 main.py[line:72] ERROR 数据写入失败:not all arguments converted during string formatting
2015-06-02 10:34:20 main.py[line:72] ERROR 数据写入失败:(1136, "Column count doesn't match value count at row 1")
2015-06-02 10:34:34 main.py[line:72] ERROR 数据写入失败:(1136, "Column count doesn't match value count at row 1")
2015-06-02 10:35:50 main.py[line:72] ERROR 数据写入失败:(1136, "Column count doesn't match value count at row 1")
2015-06-02 11:09:55 main.py[line:72] ERROR 数据写入失败:(1064, 'You have an error in your SQL syntax; check the manual that corresponds to your MySQL server version for the right syntax to use near \'\'passwd\': "\'202cb962ac59075b964b07152d234b70\'"},),birthday=\'5\xe6\x9c\x8821\',sex=\'\xe7\x94\xb7\',qq\' at line 2')
2015-06-02 18:35:33 main.py[line:96] ERROR 数据执行失败:(1064, "You have an error in your SQL syntax; check the manual that corresponds to your MySQL server version for the right syntax to use near 'FROM \n            item' at line 9")
2015-06-02 20:32:19 main.py[line:96] ERROR 数据执行失败:(1064, "You have an error in your SQL syntax; check the manual that corresponds to your MySQL server version for the right syntax to use near 'FROM \n            item' at line 9")
2015-06-02 20:32:24 main.py[line:96] ERROR 数据执行失败:(1064, "You have an error in your SQL syntax; check the manual that corresponds to your MySQL server version for the right syntax to use near 'FROM \n            item' at line 9")
2015-06-02 20:32:29 main.py[line:96] ERROR 数据执行失败:(1064, "You have an error in your SQL syntax; check the manual that corresponds to your MySQL server version for the right syntax to use near 'FROM \n            item' at line 9")
2015-06-02 20:32:32 main.py[line:96] ERROR 数据执行失败:(1064, "You have an error in your SQL syntax; check the manual that corresponds to your MySQL server version for the right syntax to use near 'FROM \n            item' at line 9")
2015-06-02 20:32:34 main.py[line:96] ERROR 数据执行失败:(1064, "You have an error in your SQL syntax; check the manual that corresponds to your MySQL server version for the right syntax to use near 'FROM \n            item' at line 9")
2015-06-02 20:33:18 main.py[line:96] ERROR 数据执行失败:(1064, "You have an error in your SQL syntax; check the manual that corresponds to your MySQL server version for the right syntax to use near 'FROM \n            item' at line 9")
2015-06-02 20:33:19 main.py[line:96] ERROR 数据执行失败:(1064, "You have an error in your SQL syntax; check the manual that corresponds to your MySQL server version for the right syntax to use near 'FROM \n            item' at line 9")
2015-06-02 20:33:21 main.py[line:96] ERROR 数据执行失败:(1064, "You have an error in your SQL syntax; check the manual that corresponds to your MySQL server version for the right syntax to use near 'FROM \n            item' at line 9")
2015-06-02 20:34:08 main.py[line:96] ERROR 数据执行失败:(1064, "You have an error in your SQL syntax; check the manual that corresponds to your MySQL server version for the right syntax to use near 'FROM \n            item' at line 9")
2015-06-02 20:34:12 main.py[line:96] ERROR 数据执行失败:(1064, "You have an error in your SQL syntax; check the manual that corresponds to your MySQL server version for the right syntax to use near 'FROM \n            item' at line 9")
2015-06-02 20:34:13 main.py[line:96] ERROR 数据执行失败:(1064, "You have an error in your SQL syntax; check the manual that corresponds to your MySQL server version for the right syntax to use near 'FROM \n            item' at line 9")
2015-06-03 10:33:47 main.py[line:99] ERROR 数据执行失败:(1054, "Unknown column 'isstart' in 'field list'")
2015-06-03 10:33:49 main.py[line:99] ERROR 数据执行失败:(1054, "Unknown column 'isstart' in 'field list'")
2015-06-03 10:34:14 main.py[line:99] ERROR 数据执行失败:(1054, "Unknown column 'isstart' in 'field list'")
2015-06-03 18:00:35 main.py[line:74] ERROR 数据写入失败:not enough arguments for format string
2015-06-03 18:01:45 main.py[line:74] ERROR 数据写入失败:not enough arguments for format string
2015-06-08 13:55:21 main.py[line:74] ERROR 数据写入失败:(1146, "Table 'task.partment' doesn't exist")
2015-06-08 15:14:30 main.py[line:98] ERROR 数据执行失败:(1054, "Unknown column 'statid' in 'field list'")
2015-06-08 15:14:33 main.py[line:98] ERROR 数据执行失败:(1054, "Unknown column 'statid' in 'field list'")
2015-06-08 15:14:35 main.py[line:98] ERROR 数据执行失败:(1054, "Unknown column 'statid' in 'field list'")
2015-06-08 15:14:36 main.py[line:98] ERROR 数据执行失败:(1054, "Unknown column 'statid' in 'field list'")
2015-06-08 15:14:38 main.py[line:98] ERROR 数据执行失败:(1054, "Unknown column 'statid' in 'field list'")
2015-06-08 15:14:42 main.py[line:98] ERROR 数据执行失败:(1054, "Unknown column 'statid' in 'field list'")
2015-06-08 15:14:43 main.py[line:98] ERROR 数据执行失败:(1054, "Unknown column 'statid' in 'field list'")
2015-06-08 15:14:48 main.py[line:98] ERROR 数据执行失败:(1054, "Unknown column 'statid' in 'field list'")
2015-06-08 15:14:50 main.py[line:98] ERROR 数据执行失败:(1054, "Unknown column 'statid' in 'field list'")
2015-06-08 15:14:52 main.py[line:98] ERROR 数据执行失败:(1054, "Unknown column 'statid' in 'field list'")
2015-06-08 15:15:05 main.py[line:98] ERROR 数据执行失败:(1054, "Unknown column 'statid' in 'field list'")
2015-06-08 15:15:06 main.py[line:98] ERROR 数据执行失败:(1054, "Unknown column 'statid' in 'field list'")
2015-06-08 15:15:08 main.py[line:98] ERROR 数据执行失败:(1054, "Unknown column 'statid' in 'field list'")
2015-06-08 15:15:09 main.py[line:98] ERROR 数据执行失败:(1054, "Unknown column 'statid' in 'field list'")
2015-06-08 15:15:38 main.py[line:98] ERROR 数据执行失败:(1054, "Unknown column 'statid' in 'field list'")
2015-06-08 15:15:38 main.py[line:98] ERROR 数据执行失败:(1054, "Unknown column 'statid' in 'field list'")
2015-06-08 15:15:38 main.py[line:98] ERROR 数据执行失败:(1054, "Unknown column 'statid' in 'field list'")
2015-06-08 15:15:38 main.py[line:98] ERROR 数据执行失败:(1054, "Unknown column 'statid' in 'field list'")
2015-06-08 15:15:41 main.py[line:98] ERROR 数据执行失败:(1054, "Unknown column 'statid' in 'field list'")
2015-06-08 15:17:15 main.py[line:98] ERROR 数据执行失败:(1054, "Unknown column 'statid' in 'field list'")
2015-06-08 15:17:19 main.py[line:98] ERROR 数据执行失败:(1054, "Unknown column 'statid' in 'field list'")
2015-06-08 15:17:21 main.py[line:98] ERROR 数据执行失败:(1054, "Unknown column 'statid' in 'field list'")
2015-06-08 15:17:22 main.py[line:98] ERROR 数据执行失败:(1054, "Unknown column 'statid' in 'field list'")
2015-06-08 15:17:24 main.py[line:98] ERROR 数据执行失败:(1054, "Unknown column 'statid' in 'field list'")
2015-06-08 15:17:54 main.py[line:98] ERROR 数据执行失败:(1054, "Unknown column 'statid' in 'field list'")
2015-06-08 15:17:56 main.py[line:98] ERROR 数据执行失败:(1054, "Unknown column 'statid' in 'field list'")
2015-06-08 15:18:00 main.py[line:98] ERROR 数据执行失败:(1054, "Unknown column 'statid' in 'field list'")
2015-06-08 15:18:56 main.py[line:98] ERROR 数据执行失败:(1054, "Unknown column 'statid' in 'field list'")
2015-06-08 15:19:00 main.py[line:98] ERROR 数据执行失败:(1054, "Unknown column 'statid' in 'field list'")
2015-06-08 15:19:05 main.py[line:98] ERROR 数据执行失败:(1054, "Unknown column 'statid' in 'field list'")
2015-06-08 15:19:18 main.py[line:98] ERROR 数据执行失败:(1054, "Unknown column 'statid' in 'field list'")
2015-06-08 15:19:19 main.py[line:98] ERROR 数据执行失败:(1054, "Unknown column 'statid' in 'field list'")
2015-06-08 15:19:20 main.py[line:98] ERROR 数据执行失败:(1054, "Unknown column 'statid' in 'field list'")
2015-06-08 15:19:21 main.py[line:98] ERROR 数据执行失败:(1054, "Unknown column 'statid' in 'field list'")
2015-06-08 15:19:22 main.py[line:98] ERROR 数据执行失败:(1054, "Unknown column 'statid' in 'field list'")
2015-06-08 15:19:24 main.py[line:98] ERROR 数据执行失败:(1054, "Unknown column 'statid' in 'field list'")
2015-06-08 15:19:26 main.py[line:98] ERROR 数据执行失败:(1054, "Unknown column 'statid' in 'field list'")
2015-06-08 15:19:27 main.py[line:98] ERROR 数据执行失败:(1054, "Unknown column 'statid' in 'field list'")
2015-06-08 15:19:28 main.py[line:98] ERROR 数据执行失败:(1054, "Unknown column 'statid' in 'field list'")
2015-06-08 15:19:45 main.py[line:98] ERROR 数据执行失败:(1054, "Unknown column 'statid' in 'field list'")
2015-06-08 15:25:58 main.py[line:98] ERROR 数据执行失败:(1054, "Unknown column 'statid' in 'field list'")
2015-06-08 15:26:06 main.py[line:98] ERROR 数据执行失败:(1054, "Unknown column 'statid' in 'field list'")
2015-06-08 15:26:07 main.py[line:98] ERROR 数据执行失败:(1054, "Unknown column 'statid' in 'field list'")
2015-06-08 15:26:09 main.py[line:98] ERROR 数据执行失败:(1054, "Unknown column 'statid' in 'field list'")
2015-06-08 15:26:18 main.py[line:98] ERROR 数据执行失败:(1054, "Unknown column 'statid' in 'field list'")
2015-06-08 15:26:23 main.py[line:98] ERROR 数据执行失败:(1054, "Unknown column 'statid' in 'field list'")
2015-06-08 15:27:25 main.py[line:98] ERROR 数据执行失败:(1054, "Unknown column 'statid' in 'field list'")
2015-06-08 15:28:19 main.py[line:98] ERROR 数据执行失败:(1054, "Unknown column 'statid' in 'field list'")
2015-06-08 15:28:43 main.py[line:98] ERROR 数据执行失败:(1054, "Unknown column 'statid' in 'field list'")
2015-06-08 15:28:43 main.py[line:98] ERROR 数据执行失败:(1054, "Unknown column 'statid' in 'field list'")
2015-06-08 15:28:52 main.py[line:98] ERROR 数据执行失败:(1054, "Unknown column 'statid' in 'field list'")
2015-06-08 15:28:54 main.py[line:98] ERROR 数据执行失败:(1054, "Unknown column 'statid' in 'field list'")
2015-06-08 15:28:56 main.py[line:98] ERROR 数据执行失败:(1054, "Unknown column 'statid' in 'field list'")
2015-06-08 15:29:39 main.py[line:98] ERROR 数据执行失败:(1054, "Unknown column 'statid' in 'field list'")
2015-06-08 15:29:39 main.py[line:98] ERROR 数据执行失败:(1054, "Unknown column 'statid' in 'field list'")
2015-06-08 15:29:39 main.py[line:98] ERROR 数据执行失败:(1054, "Unknown column 'statid' in 'field list'")
2015-06-08 15:29:40 main.py[line:98] ERROR 数据执行失败:(1054, "Unknown column 'statid' in 'field list'")
2015-06-08 15:29:43 main.py[line:98] ERROR 数据执行失败:(1054, "Unknown column 'statid' in 'field list'")
2015-06-08 15:29:44 main.py[line:98] ERROR 数据执行失败:(1054, "Unknown column 'statid' in 'field list'")
2015-06-08 15:30:35 main.py[line:98] ERROR 数据执行失败:(1054, "Unknown column 'statid' in 'field list'")
2015-06-08 15:30:39 main.py[line:98] ERROR 数据执行失败:(1054, "Unknown column 'statid' in 'field list'")
2015-06-08 15:32:44 main.py[line:98] ERROR 数据执行失败:(1054, "Unknown column 'statid' in 'field list'")
2015-06-08 15:32:46 main.py[line:98] ERROR 数据执行失败:(1054, "Unknown column 'statid' in 'field list'")
2015-06-08 15:32:47 main.py[line:98] ERROR 数据执行失败:(1054, "Unknown column 'statid' in 'field list'")
2015-06-08 15:32:48 main.py[line:98] ERROR 数据执行失败:(1054, "Unknown column 'statid' in 'field list'")
2015-06-08 15:32:49 main.py[line:98] ERROR 数据执行失败:(1054, "Unknown column 'statid' in 'field list'")
2015-06-08 15:32:55 main.py[line:98] ERROR 数据执行失败:(1054, "Unknown column 'statid' in 'field list'")
2015-06-08 15:33:15 main.py[line:98] ERROR 数据执行失败:(1054, "Unknown column 'statid' in 'field list'")
2015-06-08 15:34:39 main.py[line:98] ERROR 数据执行失败:(1054, "Unknown column 'statid' in 'field list'")
2015-06-08 16:08:25 main.py[line:74] ERROR 数据写入失败:(1064, "You have an error in your SQL syntax; check the manual that corresponds to your MySQL server version for the right syntax to use near ')' at line 3")
2015-06-08 16:10:25 main.py[line:74] ERROR 数据写入失败:(1064, "You have an error in your SQL syntax; check the manual that corresponds to your MySQL server version for the right syntax to use near ')' at line 3")
2015-06-08 16:12:08 main.py[line:74] ERROR 数据写入失败:(1064, "You have an error in your SQL syntax; check the manual that corresponds to your MySQL server version for the right syntax to use near ')' at line 3")
2015-06-08 16:15:00 main.py[line:74] ERROR 数据写入失败:(1064, "You have an error in your SQL syntax; check the manual that corresponds to your MySQL server version for the right syntax to use near ')' at line 3")
2015-06-08 16:23:48 main.py[line:98] ERROR 数据执行失败:(1054, "Unknown column 'starttime' in 'field list'")
2015-06-08 16:25:06 main.py[line:98] ERROR 数据执行失败:(1054, "Unknown column 'items' in 'field list'")
2015-06-08 16:25:15 main.py[line:98] ERROR 数据执行失败:(1054, "Unknown column 'items' in 'field list'")
2015-06-08 16:25:17 main.py[line:98] ERROR 数据执行失败:(1054, "Unknown column 'items' in 'field list'")
2015-06-08 16:25:20 main.py[line:98] ERROR 数据执行失败:(1054, "Unknown column 'items' in 'field list'")
2015-06-08 16:25:48 main.py[line:98] ERROR 数据执行失败:(1054, "Unknown column 'items' in 'field list'")
2015-06-08 16:26:46 main.py[line:98] ERROR 数据执行失败:(1054, "Unknown column 'items' in 'field list'")
2015-06-08 16:27:08 main.py[line:98] ERROR 数据执行失败:(1054, "Unknown column 'itype' in 'field list'")
2015-06-08 16:34:23 main.py[line:74] ERROR 数据写入失败:(1064, "You have an error in your SQL syntax; check the manual that corresponds to your MySQL server version for the right syntax to use near ')' at line 3")
2015-06-08 16:53:03 main.py[line:74] ERROR 数据写入失败:(1064, "You have an error in your SQL syntax; check the manual that corresponds to your MySQL server version for the right syntax to use near ')' at line 3")
2015-06-08 16:53:14 main.py[line:74] ERROR 数据写入失败:(1064, "You have an error in your SQL syntax; check the manual that corresponds to your MySQL server version for the right syntax to use near ')' at line 3")
2015-06-08 16:56:06 main.py[line:74] ERROR 数据写入失败:(1064, "You have an error in your SQL syntax; check the manual that corresponds to your MySQL server version for the right syntax to use near ')' at line 3")
2015-06-08 16:59:13 main.py[line:74] ERROR 数据写入失败:(1064, "You have an error in your SQL syntax; check the manual that corresponds to your MySQL server version for the right syntax to use near ')' at line 3")
2015-06-10 16:20:15 main.py[line:98] ERROR 数据执行失败:(1054, "Unknown column 'password' in 'where clause'")
2015-06-10 16:20:22 main.py[line:98] ERROR 数据执行失败:(1054, "Unknown column 'password' in 'where clause'")
2015-06-10 16:21:05 main.py[line:98] ERROR 数据执行失败:(1054, "Unknown column 'password' in 'where clause'")
2015-06-10 16:21:09 main.py[line:98] ERROR 数据执行失败:(1054, "Unknown column 'password' in 'where clause'")
2015-06-10 16:21:15 main.py[line:98] ERROR 数据执行失败:(1054, "Unknown column 'password' in 'where clause'")
2015-06-10 16:21:56 main.py[line:98] ERROR 数据执行失败:(1054, "Unknown column 'password' in 'where clause'")
2015-06-10 16:29:17 main.py[line:98] ERROR 数据执行失败:(1054, "Unknown column 'password' in 'where clause'")
2015-06-10 20:07:11 main.py[line:98] ERROR 数据执行失败:not all arguments converted during string formatting
2015-06-10 20:07:46 main.py[line:98] ERROR 数据执行失败:not all arguments converted during string formatting
2015-06-10 20:07:47 main.py[line:98] ERROR 数据执行失败:not all arguments converted during string formatting
2015-06-10 20:07:48 main.py[line:98] ERROR 数据执行失败:not all arguments converted during string formatting
2015-06-10 20:08:24 main.py[line:98] ERROR 数据执行失败:not all arguments converted during string formatting
2015-06-10 20:08:28 main.py[line:98] ERROR 数据执行失败:not all arguments converted during string formatting
2015-06-10 20:08:34 main.py[line:98] ERROR 数据执行失败:not all arguments converted during string formatting
2015-06-10 20:28:31 main.py[line:98] ERROR 数据执行失败:(1054, "Unknown column 'Ui.name' in 'field list'")
2015-06-10 20:28:33 main.py[line:98] ERROR 数据执行失败:(1054, "Unknown column 'Ui.name' in 'field list'")
2015-06-10 20:28:34 main.py[line:98] ERROR 数据执行失败:(1054, "Unknown column 'Ui.name' in 'field list'")
2015-06-10 20:29:32 main.py[line:98] ERROR 数据执行失败:(1054, "Unknown column 'Ui.name' in 'field list'")
2015-06-10 20:29:33 main.py[line:98] ERROR 数据执行失败:(1054, "Unknown column 'Ui.name' in 'field list'")
2015-06-10 20:29:37 main.py[line:98] ERROR 数据执行失败:(1054, "Unknown column 'Ui.name' in 'field list'")
2015-06-10 20:29:40 main.py[line:98] ERROR 数据执行失败:(1054, "Unknown column 'Ui.name' in 'field list'")
2015-06-10 20:31:22 main.py[line:98] ERROR 数据执行失败:(1054, "Unknown column 'Ui.name' in 'field list'")
2015-06-11 11:13:28 main.py[line:99] ERROR 数据执行失败:not enough arguments for format string
2015-06-11 11:13:56 main.py[line:99] ERROR 数据执行失败:not enough arguments for format string
2015-06-11 11:14:04 main.py[line:99] ERROR 数据执行失败:not enough arguments for format string
2015-06-11 11:16:14 main.py[line:99] ERROR 数据执行失败:not enough arguments for format string
2015-06-11 11:16:19 main.py[line:99] ERROR 数据执行失败:not enough arguments for format string
2015-06-11 11:16:58 main.py[line:99] ERROR 数据执行失败:not enough arguments for format string
2015-06-11 11:17:18 main.py[line:99] ERROR 数据执行失败:not enough arguments for format string
2015-06-11 11:17:37 main.py[line:99] ERROR 数据执行失败:not enough arguments for format string
2015-06-11 11:20:15 main.py[line:99] ERROR 数据执行失败:not enough arguments for format string
2015-06-11 11:20:20 main.py[line:99] ERROR 数据执行失败:not enough arguments for format string
2015-06-11 11:20:23 main.py[line:99] ERROR 数据执行失败:not enough arguments for format string
2015-06-11 11:21:28 main.py[line:99] ERROR 数据执行失败:not enough arguments for format string
2015-06-11 11:22:19 main.py[line:99] ERROR 数据执行失败:not enough arguments for format string
2015-06-11 11:22:41 main.py[line:99] ERROR 数据执行失败:(1064, "You have an error in your SQL syntax; check the manual that corresponds to your MySQL server version for the right syntax to use near ''WHERE 1=1'\n            ) AS t' at line 38")
2015-06-11 11:23:27 main.py[line:99] ERROR 数据执行失败:(1064, "You have an error in your SQL syntax; check the manual that corresponds to your MySQL server version for the right syntax to use near ''WHERE 1=1'\n            ) AS t' at line 38")
2015-06-11 11:23:30 main.py[line:99] ERROR 数据执行失败:(1064, "You have an error in your SQL syntax; check the manual that corresponds to your MySQL server version for the right syntax to use near ''WHERE 1=1'\n            ) AS t' at line 38")
2015-06-11 11:23:31 main.py[line:99] ERROR 数据执行失败:(1064, "You have an error in your SQL syntax; check the manual that corresponds to your MySQL server version for the right syntax to use near ''WHERE 1=1'\n            ) AS t' at line 38")
2015-06-11 11:42:09 main.py[line:99] ERROR 数据执行失败:(1064, "You have an error in your SQL syntax; check the manual that corresponds to your MySQL server version for the right syntax to use near 'WHERE 1=1 and (T.userid=18 or T.assistid=18 )\n            ORDER BY\n             ' at line 39")
2015-06-11 11:42:18 main.py[line:99] ERROR 数据执行失败:(1064, "You have an error in your SQL syntax; check the manual that corresponds to your MySQL server version for the right syntax to use near 'WHERE 1=1 and (T.userid=18 or T.assistid=18 )\n            ORDER BY\n             ' at line 39")
2015-06-11 11:42:21 main.py[line:99] ERROR 数据执行失败:(1064, "You have an error in your SQL syntax; check the manual that corresponds to your MySQL server version for the right syntax to use near 'WHERE 1=1 and (T.userid=18 or T.assistid=18 )\n            ORDER BY\n             ' at line 39")
2015-06-11 11:42:33 main.py[line:99] ERROR 数据执行失败:(1064, "You have an error in your SQL syntax; check the manual that corresponds to your MySQL server version for the right syntax to use near 'WHERE 1=1 and (T.userid=18 or T.assistid=18 )\n            ORDER BY\n             ' at line 39")
2015-06-11 11:42:35 main.py[line:99] ERROR 数据执行失败:(1064, "You have an error in your SQL syntax; check the manual that corresponds to your MySQL server version for the right syntax to use near 'WHERE 1=1 and (T.userid=18 or T.assistid=18 )\n            ORDER BY\n             ' at line 39")
2015-06-11 11:42:39 main.py[line:99] ERROR 数据执行失败:(1064, "You have an error in your SQL syntax; check the manual that corresponds to your MySQL server version for the right syntax to use near 'WHERE 1=1 and (T.userid=18 or T.assistid=18 )\n            ORDER BY\n             ' at line 39")
2015-06-11 11:43:47 main.py[line:99] ERROR 数据执行失败:(1064, "You have an error in your SQL syntax; check the manual that corresponds to your MySQL server version for the right syntax to use near 'WHERE 1=1 and (T.userid=18 or T.assistid=18 )\n            ORDER BY\n             ' at line 39")
2015-06-11 11:43:53 main.py[line:99] ERROR 数据执行失败:(1064, "You have an error in your SQL syntax; check the manual that corresponds to your MySQL server version for the right syntax to use near 'WHERE 1=1 and (T.userid=18 or T.assistid=18 )\n            ORDER BY\n             ' at line 39")
2015-06-11 11:44:01 main.py[line:99] ERROR 数据执行失败:(1064, "You have an error in your SQL syntax; check the manual that corresponds to your MySQL server version for the right syntax to use near 'WHERE 1=1 and (T.userid=18 or T.assistid=18 )\n            ORDER BY\n             ' at line 39")
2015-06-11 14:27:21 main.py[line:99] ERROR 数据执行失败:(1054, "Unknown column 'recovery' in 'where clause'")
2015-06-11 14:27:23 main.py[line:99] ERROR 数据执行失败:(1054, "Unknown column 'recovery' in 'where clause'")
2015-06-11 14:27:24 main.py[line:99] ERROR 数据执行失败:(1054, "Unknown column 'recovery' in 'where clause'")
2015-06-11 14:27:25 main.py[line:99] ERROR 数据执行失败:(1054, "Unknown column 'recovery' in 'where clause'")
2015-06-11 14:27:25 main.py[line:99] ERROR 数据执行失败:(1054, "Unknown column 'recovery' in 'where clause'")
2015-06-11 14:27:26 main.py[line:99] ERROR 数据执行失败:(1054, "Unknown column 'recovery' in 'where clause'")
2015-06-11 14:27:36 main.py[line:99] ERROR 数据执行失败:(1054, "Unknown column 'recovery' in 'where clause'")
2015-06-11 14:27:55 main.py[line:99] ERROR 数据执行失败:(1054, "Unknown column 'recovery' in 'where clause'")
2015-06-11 14:27:56 main.py[line:99] ERROR 数据执行失败:(1054, "Unknown column 'recovery' in 'where clause'")
2015-06-11 14:27:57 main.py[line:99] ERROR 数据执行失败:(1054, "Unknown column 'recovery' in 'where clause'")
2015-06-11 14:27:57 main.py[line:99] ERROR 数据执行失败:(1054, "Unknown column 'recovery' in 'where clause'")
2015-06-11 14:28:02 main.py[line:99] ERROR 数据执行失败:(1054, "Unknown column 'recovery' in 'where clause'")
2015-06-11 14:28:04 main.py[line:99] ERROR 数据执行失败:(1054, "Unknown column 'recovery' in 'where clause'")
2015-06-11 14:50:53 main.py[line:75] ERROR 数据写入失败:(1064, "You have an error in your SQL syntax; check the manual that corresponds to your MySQL server version for the right syntax to use near 'del_status=0\n        WHERE\n            id='5'' at line 5")
2015-06-11 14:52:05 main.py[line:75] ERROR 数据写入失败:(1064, "You have an error in your SQL syntax; check the manual that corresponds to your MySQL server version for the right syntax to use near 'del_status=0\n        WHERE\n            id='5'' at line 5")
2015-06-11 15:21:23 main.py[line:77] ERROR 数据写入失败:not enough arguments for format string
2015-06-11 15:22:00 main.py[line:73] ERROR 数据写入失败:not enough arguments for format string
2015-06-11 15:36:14 main.py[line:97] ERROR 数据执行失败:(1052, "Column 'del_status' in where clause is ambiguous")
2015-06-11 15:38:07 main.py[line:97] ERROR 数据执行失败:(1052, "Column 'del_status' in where clause is ambiguous")
2015-06-11 15:40:13 main.py[line:97] ERROR 数据执行失败:(1052, "Column 'del_status' in where clause is ambiguous")
2015-06-11 15:41:08 main.py[line:97] ERROR 数据执行失败:(1052, "Column 'del_status' in where clause is ambiguous")
2015-06-11 16:03:15 main.py[line:97] ERROR 数据执行失败:(1052, "Column 'del_status' in where clause is ambiguous")
2015-06-11 16:09:42 main.py[line:98] ERROR 数据执行失败:(1052, "Column 'del_status' in where clause is ambiguous")
2015-06-11 16:12:24 main.py[line:94] ERROR 数据执行失败:(1066, "Not unique table/alias: 'U'")
2015-06-11 16:12:27 main.py[line:94] ERROR 数据执行失败:(1066, "Not unique table/alias: 'U'")
2015-06-11 16:12:29 main.py[line:94] ERROR 数据执行失败:(1066, "Not unique table/alias: 'U'")
2015-06-11 16:15:34 main.py[line:94] ERROR 数据执行失败:(1052, "Column 'del_status' in where clause is ambiguous")
2015-06-11 16:15:36 main.py[line:94] ERROR 数据执行失败:(1052, "Column 'del_status' in where clause is ambiguous")
2015-06-11 16:15:36 main.py[line:94] ERROR 数据执行失败:(1052, "Column 'del_status' in where clause is ambiguous")
2015-06-11 16:15:37 main.py[line:94] ERROR 数据执行失败:(1052, "Column 'del_status' in where clause is ambiguous")
2015-06-11 16:15:38 main.py[line:94] ERROR 数据执行失败:(1052, "Column 'del_status' in where clause is ambiguous")
2015-06-11 16:15:39 main.py[line:94] ERROR 数据执行失败:(1052, "Column 'del_status' in where clause is ambiguous")
2015-06-11 16:15:40 main.py[line:94] ERROR 数据执行失败:(1052, "Column 'del_status' in where clause is ambiguous")
2015-06-11 16:15:41 main.py[line:94] ERROR 数据执行失败:(1052, "Column 'del_status' in where clause is ambiguous")
2015-06-11 16:15:44 main.py[line:94] ERROR 数据执行失败:(1052, "Column 'del_status' in where clause is ambiguous")
2015-06-11 16:15:45 main.py[line:94] ERROR 数据执行失败:(1052, "Column 'del_status' in where clause is ambiguous")
2015-06-11 16:15:46 main.py[line:94] ERROR 数据执行失败:(1052, "Column 'del_status' in where clause is ambiguous")
2015-06-11 16:15:46 main.py[line:94] ERROR 数据执行失败:(1052, "Column 'del_status' in where clause is ambiguous")
2015-06-11 16:15:53 main.py[line:94] ERROR 数据执行失败:(1052, "Column 'del_status' in where clause is ambiguous")
2015-06-11 16:16:13 main.py[line:94] ERROR 数据执行失败:(1052, "Column 'del_status' in where clause is ambiguous")
2015-06-11 16:16:15 main.py[line:94] ERROR 数据执行失败:(1052, "Column 'del_status' in where clause is ambiguous")
2015-06-11 16:16:16 main.py[line:94] ERROR 数据执行失败:(1052, "Column 'del_status' in where clause is ambiguous")
2015-06-11 16:16:19 main.py[line:94] ERROR 数据执行失败:(1052, "Column 'del_status' in where clause is ambiguous")
2015-06-11 16:16:28 main.py[line:94] ERROR 数据执行失败:(1052, "Column 'del_status' in where clause is ambiguous")
2015-06-11 16:16:34 main.py[line:94] ERROR 数据执行失败:(1052, "Column 'del_status' in where clause is ambiguous")
2015-06-11 16:19:29 main.py[line:94] ERROR 数据执行失败:(1052, "Column 'del_status' in where clause is ambiguous")
2015-06-11 16:19:30 main.py[line:94] ERROR 数据执行失败:(1052, "Column 'del_status' in where clause is ambiguous")
2015-06-11 16:19:31 main.py[line:94] ERROR 数据执行失败:(1052, "Column 'del_status' in where clause is ambiguous")
2015-06-11 16:19:31 main.py[line:94] ERROR 数据执行失败:(1052, "Column 'del_status' in where clause is ambiguous")
2015-06-11 16:19:31 main.py[line:94] ERROR 数据执行失败:(1052, "Column 'del_status' in where clause is ambiguous")
2015-06-11 16:19:32 main.py[line:94] ERROR 数据执行失败:(1052, "Column 'del_status' in where clause is ambiguous")
2015-06-11 16:19:32 main.py[line:94] ERROR 数据执行失败:(1052, "Column 'del_status' in where clause is ambiguous")
2015-06-11 16:20:42 main.py[line:94] ERROR 数据执行失败:(1052, "Column 'del_status' in where clause is ambiguous")
2015-06-11 16:21:00 main.py[line:94] ERROR 数据执行失败:(1052, "Column 'del_status' in where clause is ambiguous")
2015-06-12 10:00:27 main.py[line:94] ERROR 数据执行失败:(1064, "You have an error in your SQL syntax; check the manual that corresponds to your MySQL server version for the right syntax to use near 'FROM\n            item AS I\n            LEFT OUTER JOIN user AS U on I.userid = U' at line 11")
2018-04-27 21:07:48 main.py[line:88] ERROR 数据库连接失败:(1049, "Unknown database 'team'")
2018-04-27 21:07:50 main.py[line:88] ERROR 数据库连接失败:(1049, "Unknown database 'team'")
2018-04-27 21:07:50 main.py[line:88] ERROR 数据库连接失败:(1049, "Unknown database 'team'")
2018-04-27 21:07:50 main.py[line:88] ERROR 数据库连接失败:(1049, "Unknown database 'team'")
2018-04-27 21:08:16 main.py[line:88] ERROR 数据库连接失败:(1049, "Unknown database 'team'")
2018-04-27 21:08:28 main.py[line:88] ERROR 数据库连接失败:(1049, "Unknown database 'team'")
2018-04-27 21:08:28 main.py[line:88] ERROR 数据库连接失败:(1049, "Unknown database 'team'")
2018-04-27 21:08:28 main.py[line:88] ERROR 数据库连接失败:(1049, "Unknown database 'team'")
2018-04-27 21:08:31 main.py[line:88] ERROR 数据库连接失败:(1049, "Unknown database 'team'")
2018-04-27 23:02:16 main.py[line:71] ERROR 数据写入失败:not all arguments converted during string formatting
2018-04-27 23:02:24 main.py[line:71] ERROR 数据写入失败:not all arguments converted during string formatting
2018-04-27 23:02:33 main.py[line:71] ERROR 数据写入失败:not all arguments converted during string formatting
2018-04-27 23:02:36 main.py[line:71] ERROR 数据写入失败:not all arguments converted during string formatting
2018-04-27 23:03:54 main.py[line:71] ERROR 数据写入失败:not all arguments converted during string formatting
2018-04-27 23:04:00 main.py[line:71] ERROR 数据写入失败:not all arguments converted during string formatting
2018-04-27 23:04:07 main.py[line:71] ERROR 数据写入失败:not all arguments converted during string formatting
2018-04-27 23:04:14 main.py[line:71] ERROR 数据写入失败:not all arguments converted during string formatting
2018-04-27 23:06:13 main.py[line:71] ERROR 数据写入失败:not all arguments converted during string formatting
2018-04-27 23:44:08 main.py[line:95] ERROR 数据执行失败:(1064, "You have an error in your SQL syntax; check the manual that corresponds to your MySQL server version for the right syntax to use near 'CASE U.access WHEN '0' THEN '\xe5\xad\xa6\xe5\x91\x98' WHEN '1' THEN '\xe7\xae\xa1\xe7\x90\x86\xe5\x91\x98' WHEN '2' THEN '' at line 13")
2018-04-27 23:44:28 main.py[line:95] ERROR 数据执行失败:(1064, "You have an error in your SQL syntax; check the manual that corresponds to your MySQL server version for the right syntax to use near 'CASE U.access WHEN 0 THEN '\xe5\xad\xa6\xe5\x91\x98' WHEN 1 THEN '\xe7\xae\xa1\xe7\x90\x86\xe5\x91\x98' WHEN 2 THEN '\xe8\xb4\x9f\xe8\xb4\xa3' at line 13")
2018-04-27 23:44:44 main.py[line:95] ERROR 数据执行失败:(1064, "You have an error in your SQL syntax; check the manual that corresponds to your MySQL server version for the right syntax to use near 'FROM\n        user as U\n        LEFT OUTER JOIN department as D on U.department=D' at line 14")
2018-04-29 20:36:40 main.py[line:88] ERROR 数据库连接失败:(2003, "Can't connect to MySQL server on 'localhost' (10061)")
2018-04-29 20:53:26 main.py[line:95] ERROR 数据执行失败:(1054, "Unknown column 'U.qq' in 'field list'")
2018-04-29 20:59:27 main.py[line:95] ERROR 数据执行失败:(1054, "Unknown column 'U.department' in 'on clause'")
2018-04-29 20:59:30 main.py[line:95] ERROR 数据执行失败:(1054, "Unknown column 'U.department' in 'on clause'")
2018-04-29 21:00:35 main.py[line:95] ERROR 数据执行失败:(1054, "Unknown column 'U.department' in 'on clause'")
2018-04-29 21:02:43 main.py[line:71] ERROR 数据写入失败:(1054, "Unknown column 'qq' in 'field list'")
2018-04-29 21:02:56 main.py[line:71] ERROR 数据写入失败:(1054, "Unknown column 'qq' in 'field list'")
2018-04-29 21:03:01 main.py[line:71] ERROR 数据写入失败:(1054, "Unknown column 'qq' in 'field list'")
2018-04-29 21:03:08 main.py[line:71] ERROR 数据写入失败:(1054, "Unknown column 'qq' in 'field list'")
2018-04-29 21:03:10 main.py[line:71] ERROR 数据写入失败:(1054, "Unknown column 'qq' in 'field list'")
2018-04-29 21:03:25 main.py[line:71] ERROR 数据写入失败:(1054, "Unknown column 'qq' in 'field list'")
2018-04-29 21:03:28 main.py[line:71] ERROR 数据写入失败:(1054, "Unknown column 'qq' in 'field list'")
2018-04-29 21:03:36 main.py[line:95] ERROR 数据执行失败:not all arguments converted during string formatting
2018-04-29 21:23:27 main.py[line:95] ERROR 数据执行失败:(1305, 'FUNCTION task.data_format does not exist')
2018-04-29 21:24:49 main.py[line:95] ERROR 数据执行失败:(1305, 'FUNCTION task.data_format does not exist')
2018-04-29 21:26:10 main.py[line:95] ERROR 数据执行失败:(1305, 'FUNCTION task.data_format does not exist')
2018-04-30 15:41:17 main.py[line:95] ERROR 数据执行失败:(1054, "Unknown column 'T.priority' in 'field list'")
2018-04-30 22:35:20 main.py[line:95] ERROR 数据执行失败:not all arguments converted during string formatting
2018-04-30 22:35:20 main.py[line:95] ERROR 数据执行失败:not all arguments converted during string formatting
2018-04-30 22:44:47 main.py[line:95] ERROR 数据执行失败:not all arguments converted during string formatting
2018-04-30 22:44:47 main.py[line:95] ERROR 数据执行失败:not all arguments converted during string formatting
2018-04-30 22:45:27 main.py[line:95] ERROR 数据执行失败:not all arguments converted during string formatting
2018-04-30 22:45:27 main.py[line:95] ERROR 数据执行失败:not all arguments converted during string formatting
2018-04-30 22:46:32 main.py[line:95] ERROR 数据执行失败:not all arguments converted during string formatting
2018-04-30 22:46:32 main.py[line:95] ERROR 数据执行失败:not all arguments converted during string formatting
2018-04-30 22:46:51 main.py[line:95] ERROR 数据执行失败:not all arguments converted during string formatting
2018-04-30 22:46:51 main.py[line:95] ERROR 数据执行失败:not all arguments converted during string formatting
2018-04-30 22:52:02 main.py[line:95] ERROR 数据执行失败:not all arguments converted during string formatting
2018-04-30 22:52:02 main.py[line:95] ERROR 数据执行失败:not all arguments converted during string formatting
2018-04-30 22:52:28 main.py[line:95] ERROR 数据执行失败:not all arguments converted during string formatting
2018-04-30 22:52:28 main.py[line:95] ERROR 数据执行失败:not all arguments converted during string formatting
2018-04-30 22:53:17 main.py[line:95] ERROR 数据执行失败:not all arguments converted during string formatting
2018-04-30 22:53:17 main.py[line:95] ERROR 数据执行失败:not all arguments converted during string formatting
2018-04-30 22:54:19 main.py[line:95] ERROR 数据执行失败:not all arguments converted during string formatting
2018-04-30 22:54:19 main.py[line:95] ERROR 数据执行失败:not all arguments converted during string formatting
2018-04-30 22:55:25 main.py[line:95] ERROR 数据执行失败:not all arguments converted during string formatting
2018-04-30 22:55:25 main.py[line:95] ERROR 数据执行失败:not all arguments converted during string formatting
2018-04-30 22:57:08 main.py[line:95] ERROR 数据执行失败:not all arguments converted during string formatting
2018-04-30 22:57:08 main.py[line:95] ERROR 数据执行失败:not all arguments converted during string formatting
2018-04-30 22:58:18 main.py[line:95] ERROR 数据执行失败:not all arguments converted during string formatting
2018-04-30 22:58:18 main.py[line:95] ERROR 数据执行失败:not all arguments converted during string formatting
2018-04-30 22:59:38 main.py[line:95] ERROR 数据执行失败:not all arguments converted during string formatting
2018-04-30 22:59:38 main.py[line:95] ERROR 数据执行失败:not all arguments converted during string formatting
2018-04-30 23:00:27 main.py[line:95] ERROR 数据执行失败:not all arguments converted during string formatting
2018-04-30 23:00:27 main.py[line:95] ERROR 数据执行失败:not all arguments converted during string formatting
2018-04-30 23:04:19 main.py[line:95] ERROR 数据执行失败:not all arguments converted during string formatting
2018-04-30 23:04:19 main.py[line:95] ERROR 数据执行失败:not all arguments converted during string formatting
2018-04-30 23:06:18 main.py[line:95] ERROR 数据执行失败:not all arguments converted during string formatting
2018-04-30 23:06:18 main.py[line:95] ERROR 数据执行失败:not all arguments converted during string formatting
2018-04-30 23:06:20 main.py[line:95] ERROR 数据执行失败:not all arguments converted during string formatting
2018-04-30 23:06:20 main.py[line:95] ERROR 数据执行失败:not all arguments converted during string formatting
2018-04-30 23:06:23 main.py[line:95] ERROR 数据执行失败:not all arguments converted during string formatting
2018-04-30 23:06:23 main.py[line:95] ERROR 数据执行失败:not all arguments converted during string formatting
2018-04-30 23:19:28 main.py[line:95] ERROR 数据执行失败:not all arguments converted during string formatting
2018-04-30 23:20:18 main.py[line:95] ERROR 数据执行失败:not all arguments converted during string formatting
2018-04-30 23:20:22 main.py[line:95] ERROR 数据执行失败:not all arguments converted during string formatting
2018-04-30 23:21:26 main.py[line:95] ERROR 数据执行失败:not all arguments converted during string formatting
2018-04-30 23:21:38 main.py[line:95] ERROR 数据执行失败:not all arguments converted during string formatting
2018-04-30 23:22:22 main.py[line:95] ERROR 数据执行失败:not enough arguments for format string
2018-04-30 23:24:03 main.py[line:96] ERROR 数据执行失败:not enough arguments for format string
2018-04-30 23:25:16 main.py[line:96] ERROR 数据执行失败:not all arguments converted during string formatting
2018-04-30 23:26:53 main.py[line:96] ERROR 数据执行失败:not all arguments converted during string formatting
2018-04-30 23:28:06 main.py[line:96] ERROR 数据执行失败:not all arguments converted during string formatting
2018-04-30 23:33:10 main.py[line:96] ERROR 数据执行失败:not all arguments converted during string formatting
2018-05-06 16:49:44 main.py[line:96] ERROR 数据执行失败:not all arguments converted during string formatting
2018-05-06 18:10:29 main.py[line:71] ERROR 数据写入失败:(1452, 'Cannot add or update a child row: a foreign key constraint fails (`task`.`user`, CONSTRAINT `user_ibfk_1` FOREIGN KEY (`teamname`) REFERENCES `team` (`name`) ON DELETE NO ACTION ON UPDATE NO ACTION)')
2018-05-06 18:10:30 main.py[line:71] ERROR 数据写入失败:(1452, 'Cannot add or update a child row: a foreign key constraint fails (`task`.`user`, CONSTRAINT `user_ibfk_1` FOREIGN KEY (`teamname`) REFERENCES `team` (`name`) ON DELETE NO ACTION ON UPDATE NO ACTION)')
2018-05-06 18:10:30 main.py[line:71] ERROR 数据写入失败:(1452, 'Cannot add or update a child row: a foreign key constraint fails (`task`.`user`, CONSTRAINT `user_ibfk_1` FOREIGN KEY (`teamname`) REFERENCES `team` (`name`) ON DELETE NO ACTION ON UPDATE NO ACTION)')
2018-05-06 18:10:30 main.py[line:71] ERROR 数据写入失败:(1452, 'Cannot add or update a child row: a foreign key constraint fails (`task`.`user`, CONSTRAINT `user_ibfk_1` FOREIGN KEY (`teamname`) REFERENCES `team` (`name`) ON DELETE NO ACTION ON UPDATE NO ACTION)')
2018-05-06 18:10:36 main.py[line:71] ERROR 数据写入失败:(1452, 'Cannot add or update a child row: a foreign key constraint fails (`task`.`user`, CONSTRAINT `user_ibfk_1` FOREIGN KEY (`teamname`) REFERENCES `team` (`name`) ON DELETE NO ACTION ON UPDATE NO ACTION)')
2018-05-06 18:13:52 main.py[line:71] ERROR 数据写入失败:(1452, 'Cannot add or update a child row: a foreign key constraint fails (`task`.`user`, CONSTRAINT `user_ibfk_1` FOREIGN KEY (`teamname`) REFERENCES `team` (`name`) ON DELETE NO ACTION ON UPDATE NO ACTION)')
2018-05-06 18:14:08 main.py[line:71] ERROR 数据写入失败:(1452, 'Cannot add or update a child row: a foreign key constraint fails (`task`.`user`, CONSTRAINT `user_ibfk_1` FOREIGN KEY (`teamname`) REFERENCES `team` (`name`) ON DELETE NO ACTION ON UPDATE NO ACTION)')
2018-05-06 18:14:18 main.py[line:71] ERROR 数据写入失败:(1452, 'Cannot add or update a child row: a foreign key constraint fails (`task`.`user`, CONSTRAINT `user_ibfk_1` FOREIGN KEY (`teamname`) REFERENCES `team` (`name`) ON DELETE NO ACTION ON UPDATE NO ACTION)')
2018-05-06 19:45:23 main.py[line:71] ERROR 数据写入失败:(1451, 'Cannot delete or update a parent row: a foreign key constraint fails (`task`.`user`, CONSTRAINT `user_ibfk_1` FOREIGN KEY (`teamname`) REFERENCES `team` (`name`) ON DELETE NO ACTION ON UPDATE NO ACTION)')
2018-05-06 23:41:25 main.py[line:71] ERROR 数据写入失败:(1451, 'Cannot delete or update a parent row: a foreign key constraint fails (`task`.`user`, CONSTRAINT `user_ibfk_1` FOREIGN KEY (`teamname`) REFERENCES `team` (`name`) ON DELETE NO ACTION ON UPDATE NO ACTION)')
2018-05-06 23:42:23 main.py[line:71] ERROR 数据写入失败:(1451, 'Cannot delete or update a parent row: a foreign key constraint fails (`task`.`user`, CONSTRAINT `user_ibfk_1` FOREIGN KEY (`teamname`) REFERENCES `team` (`name`) ON DELETE NO ACTION ON UPDATE NO ACTION)')
2018-05-06 23:46:26 main.py[line:71] ERROR 数据写入失败:(1451, 'Cannot delete or update a parent row: a foreign key constraint fails (`task`.`user`, CONSTRAINT `user_ibfk_1` FOREIGN KEY (`teamname`) REFERENCES `team` (`name`) ON DELETE NO ACTION ON UPDATE NO ACTION)')
2018-05-07 00:02:15 main.py[line:71] ERROR 数据写入失败:(1452, 'Cannot add or update a child row: a foreign key constraint fails (`task`.`user`, CONSTRAINT `user_ibfk_4` FOREIGN KEY (`teamname`) REFERENCES `team` (`name`) ON DELETE SET NULL ON UPDATE SET NULL)')
2018-05-07 00:02:24 main.py[line:71] ERROR 数据写入失败:(1452, 'Cannot add or update a child row: a foreign key constraint fails (`task`.`user`, CONSTRAINT `user_ibfk_4` FOREIGN KEY (`teamname`) REFERENCES `team` (`name`) ON DELETE SET NULL ON UPDATE SET NULL)')
2018-05-07 00:02:25 main.py[line:71] ERROR 数据写入失败:(1452, 'Cannot add or update a child row: a foreign key constraint fails (`task`.`user`, CONSTRAINT `user_ibfk_4` FOREIGN KEY (`teamname`) REFERENCES `team` (`name`) ON DELETE SET NULL ON UPDATE SET NULL)')
2018-05-07 00:02:26 main.py[line:71] ERROR 数据写入失败:(1452, 'Cannot add or update a child row: a foreign key constraint fails (`task`.`user`, CONSTRAINT `user_ibfk_4` FOREIGN KEY (`teamname`) REFERENCES `team` (`name`) ON DELETE SET NULL ON UPDATE SET NULL)')
2018-05-07 00:02:26 main.py[line:71] ERROR 数据写入失败:(1452, 'Cannot add or update a child row: a foreign key constraint fails (`task`.`user`, CONSTRAINT `user_ibfk_4` FOREIGN KEY (`teamname`) REFERENCES `team` (`name`) ON DELETE SET NULL ON UPDATE SET NULL)')
2018-05-07 00:02:26 main.py[line:71] ERROR 数据写入失败:(1452, 'Cannot add or update a child row: a foreign key constraint fails (`task`.`user`, CONSTRAINT `user_ibfk_4` FOREIGN KEY (`teamname`) REFERENCES `team` (`name`) ON DELETE SET NULL ON UPDATE SET NULL)')
2018-05-07 00:02:26 main.py[line:71] ERROR 数据写入失败:(1452, 'Cannot add or update a child row: a foreign key constraint fails (`task`.`user`, CONSTRAINT `user_ibfk_4` FOREIGN KEY (`teamname`) REFERENCES `team` (`name`) ON DELETE SET NULL ON UPDATE SET NULL)')
2018-05-07 00:02:27 main.py[line:71] ERROR 数据写入失败:(1452, 'Cannot add or update a child row: a foreign key constraint fails (`task`.`user`, CONSTRAINT `user_ibfk_4` FOREIGN KEY (`teamname`) REFERENCES `team` (`name`) ON DELETE SET NULL ON UPDATE SET NULL)')
2018-05-07 00:02:27 main.py[line:71] ERROR 数据写入失败:(1452, 'Cannot add or update a child row: a foreign key constraint fails (`task`.`user`, CONSTRAINT `user_ibfk_4` FOREIGN KEY (`teamname`) REFERENCES `team` (`name`) ON DELETE SET NULL ON UPDATE SET NULL)')
2018-05-07 00:02:27 main.py[line:71] ERROR 数据写入失败:(1452, 'Cannot add or update a child row: a foreign key constraint fails (`task`.`user`, CONSTRAINT `user_ibfk_4` FOREIGN KEY (`teamname`) REFERENCES `team` (`name`) ON DELETE SET NULL ON UPDATE SET NULL)')
2018-05-07 00:02:36 main.py[line:71] ERROR 数据写入失败:(1452, 'Cannot add or update a child row: a foreign key constraint fails (`task`.`user`, CONSTRAINT `user_ibfk_4` FOREIGN KEY (`teamname`) REFERENCES `team` (`name`) ON DELETE SET NULL ON UPDATE SET NULL)')
2018-05-07 00:02:45 main.py[line:71] ERROR 数据写入失败:(1452, 'Cannot add or update a child row: a foreign key constraint fails (`task`.`user`, CONSTRAINT `user_ibfk_4` FOREIGN KEY (`teamname`) REFERENCES `team` (`name`) ON DELETE SET NULL ON UPDATE SET NULL)')
2018-05-07 00:04:30 main.py[line:71] ERROR 数据写入失败:(1452, 'Cannot add or update a child row: a foreign key constraint fails (`task`.`user`, CONSTRAINT `user_ibfk_4` FOREIGN KEY (`teamname`) REFERENCES `team` (`name`) ON DELETE SET NULL ON UPDATE SET NULL)')
2018-05-07 00:05:20 main.py[line:71] ERROR 数据写入失败:(1452, 'Cannot add or update a child row: a foreign key constraint fails (`task`.`user`, CONSTRAINT `user_ibfk_4` FOREIGN KEY (`teamname`) REFERENCES `team` (`name`) ON DELETE SET NULL ON UPDATE SET NULL)')
2018-05-07 00:06:53 main.py[line:71] ERROR 数据写入失败:(1452, 'Cannot add or update a child row: a foreign key constraint fails (`task`.`user`, CONSTRAINT `user_ibfk_4` FOREIGN KEY (`teamname`) REFERENCES `team` (`name`) ON DELETE SET NULL ON UPDATE SET NULL)')
2018-05-07 00:08:48 main.py[line:71] ERROR 数据写入失败:not all arguments converted during string formatting
2018-05-07 00:08:54 main.py[line:71] ERROR 数据写入失败:not all arguments converted during string formatting
2018-05-07 00:10:40 main.py[line:71] ERROR 数据写入失败:(1452, 'Cannot add or update a child row: a foreign key constraint fails (`task`.`user`, CONSTRAINT `user_ibfk_4` FOREIGN KEY (`teamname`) REFERENCES `team` (`name`) ON DELETE SET NULL ON UPDATE SET NULL)')
2018-05-07 00:13:00 main.py[line:71] ERROR 数据写入失败:not all arguments converted during string formatting
2018-05-07 00:13:08 main.py[line:71] ERROR 数据写入失败:not all arguments converted during string formatting
2018-05-07 17:06:53 main.py[line:88] ERROR 数据库连接失败:(2003, "Can't connect to MySQL server on 'localhost' (10061)")
2018-05-07 23:15:36 main.py[line:96] ERROR 数据执行失败:(1054, "Unknown column 'T.day' in 'field list'")
2018-05-07 23:16:14 main.py[line:96] ERROR 数据执行失败:(1054, "Unknown column 'T.day' in 'field list'")
2018-05-07 23:36:46 main.py[line:96] ERROR 数据执行失败:(1054, "Unknown column 'itemid' in 'field list'")
2018-05-07 23:47:42 main.py[line:71] ERROR 数据写入失败:(1054, "Unknown column 'planname' in 'field list'")
2018-05-07 23:49:15 main.py[line:71] ERROR 数据写入失败:(1054, "Unknown column 'planname' in 'field list'")
2018-05-07 23:51:22 main.py[line:96] ERROR 数据执行失败:(1054, "Unknown column 'T.priority' in 'field list'")
2018-05-07 23:51:32 main.py[line:96] ERROR 数据执行失败:(1054, "Unknown column 'itemid' in 'field list'")
2018-05-07 23:59:48 main.py[line:96] ERROR 数据执行失败:(1054, "Unknown column 'T.day' in 'field list'")
2018-06-06 23:38:12 main.py[line:96] ERROR 数据执行失败:(1054, "Unknown column 'inputid' in 'field list'")
2018-06-07 09:23:39 main.py[line:96] ERROR 数据执行失败:(1146, "Table 'task.department' doesn't exist")
2018-06-07 09:24:00 main.py[line:96] ERROR 数据执行失败:(1146, "Table 'task.department' doesn't exist")
2018-06-07 09:27:57 main.py[line:96] ERROR 数据执行失败:(1146, "Table 'task.department' doesn't exist")
2018-06-07 09:27:58 main.py[line:96] ERROR 数据执行失败:(1146, "Table 'task.department' doesn't exist")
2018-06-07 09:28:21 main.py[line:96] ERROR 数据执行失败:(1146, "Table 'task.department' doesn't exist")
2018-06-07 09:30:15 main.py[line:71] ERROR 数据写入失败:(1452, 'Cannot add or update a child row: a foreign key constraint fails (`task`.`user`, CONSTRAINT `user_ibfk_4` FOREIGN KEY (`teamname`) REFERENCES `team` (`name`) ON DELETE SET NULL ON UPDATE SET NULL)')
2018-06-08 21:33:08 main.py[line:96] ERROR 数据执行失败:not all arguments converted during string formatting
2018-06-08 21:45:06 main.py[line:96] ERROR 数据执行失败:not all arguments converted during string formatting
2018-06-08 21:45:07 main.py[line:96] ERROR 数据执行失败:not all arguments converted during string formatting
2018-06-08 21:46:05 main.py[line:96] ERROR 数据执行失败:not all arguments converted during string formatting
2018-06-08 23:24:12 main.py[line:96] ERROR 数据执行失败:(1271, "Illegal mix of collations for operation '='")
2018-06-08 23:24:33 main.py[line:96] ERROR 数据执行失败:(1271, "Illegal mix of collations for operation '='")
2018-06-08 23:25:13 main.py[line:96] ERROR 数据执行失败:(1271, "Illegal mix of collations for operation '='")
2018-06-08 23:53:41 main.py[line:96] ERROR 数据执行失败:(1271, "Illegal mix of collations for operation '='")
2018-06-09 10:13:43 main.py[line:96] ERROR 数据执行失败:(1146, "Table 'task.item' doesn't exist")
2018-06-09 10:13:43 main.py[line:96] ERROR 数据执行失败:(1146, "Table 'task.department' doesn't exist")
2018-06-09 17:18:35 main.py[line:71] ERROR 数据写入失败:sequence item 0: expected string, dict found
2018-06-09 17:20:06 main.py[line:71] ERROR 数据写入失败:sequence item 0: expected string, dict found
2018-06-09 17:23:09 main.py[line:71] ERROR 数据写入失败:(1054, "Unknown column 'subject' in 'field list'")
2018-06-09 17:24:43 main.py[line:71] ERROR 数据写入失败:(1054, "Unknown column 'subject' in 'field list'")
2018-06-09 17:31:32 main.py[line:71] ERROR 数据写入失败:(1452, 'Cannot add or update a child row: a foreign key constraint fails (`task`.`scorelist`, CONSTRAINT `scorelist_ibfk_1` FOREIGN KEY (`inputid`) REFERENCES `user` (`id`) ON DELETE NO ACTION ON UPDATE NO ACTION)')
2018-06-09 20:13:18 main.py[line:96] ERROR 数据执行失败:%d format: a number is required, not str
2018-06-10 23:11:33 main.py[line:96] ERROR 数据执行失败:(1146, "Table 'task.item' doesn't exist")
2018-06-10 23:11:33 main.py[line:96] ERROR 数据执行失败:(1146, "Table 'task.department' doesn't exist")
2018-06-10 23:26:24 main.py[line:96] ERROR 数据执行失败:(1054, "Unknown column 'T.planname' in 'field list'")
2018-06-10 23:31:00 main.py[line:96] ERROR 数据执行失败:(1054, "Unknown column 'T.inputid' in 'field list'")
2018-06-10 23:31:04 main.py[line:96] ERROR 数据执行失败:(1054, "Unknown column 'T.inputid' in 'field list'")
2018-06-10 23:48:34 main.py[line:96] ERROR 数据执行失败:(1054, "Unknown column 'ts.date' in 'field list'")
2018-06-10 23:48:40 main.py[line:96] ERROR 数据执行失败:(1054, "Unknown column 'ts.date' in 'field list'")
2018-06-11 14:35:31 main.py[line:96] ERROR 数据执行失败:(1146, "Table 'task.item' doesn't exist")
2018-06-11 14:35:31 main.py[line:96] ERROR 数据执行失败:(1146, "Table 'task.department' doesn't exist")
2018-06-11 15:27:18 main.py[line:96] ERROR 数据执行失败:not all arguments converted during string formatting
2018-06-11 15:27:24 main.py[line:96] ERROR 数据执行失败:not all arguments converted during string formatting
2018-06-11 15:27:44 main.py[line:96] ERROR 数据执行失败:not all arguments converted during string formatting
2018-06-11 15:27:45 main.py[line:96] ERROR 数据执行失败:not all arguments converted during string formatting
2018-06-11 15:27:45 main.py[line:96] ERROR 数据执行失败:not all arguments converted during string formatting
2018-06-11 15:27:49 main.py[line:96] ERROR 数据执行失败:not all arguments converted during string formatting
2018-06-11 15:28:55 main.py[line:96] ERROR 数据执行失败:(1146, "Table 'task.item' doesn't exist")
2018-06-11 15:28:55 main.py[line:96] ERROR 数据执行失败:(1146, "Table 'task.department' doesn't exist")
2018-06-11 19:30:42 main.py[line:96] ERROR 数据执行失败:(1146, "Table 'task.item' doesn't exist")
2018-06-11 19:30:42 main.py[line:96] ERROR 数据执行失败:(1146, "Table 'task.department' doesn't exist")
2018-06-11 19:31:04 main.py[line:96] ERROR 数据执行失败:(1146, "Table 'task.item' doesn't exist")
2018-06-11 19:31:04 main.py[line:96] ERROR 数据执行失败:(1146, "Table 'task.department' doesn't exist")
2018-06-11 20:25:33 main.py[line:71] ERROR 数据写入失败:(1452, 'Cannot add or update a child row: a foreign key constraint fails (`task`.`task`, CONSTRAINT `task_ibfk_12` FOREIGN KEY (`place`) REFERENCES `pplace` (`place`) ON DELETE SET NULL ON UPDATE CASCADE)')
2018-06-11 20:25:42 main.py[line:71] ERROR 数据写入失败:(1452, 'Cannot add or update a child row: a foreign key constraint fails (`task`.`task`, CONSTRAINT `task_ibfk_12` FOREIGN KEY (`place`) REFERENCES `pplace` (`place`) ON DELETE SET NULL ON UPDATE CASCADE)')
2018-06-11 23:35:15 main.py[line:96] ERROR 数据执行失败:(1146, "Table 'task.item' doesn't exist")
2018-06-11 23:35:15 main.py[line:96] ERROR 数据执行失败:(1146, "Table 'task.department' doesn't exist")
2018-06-14 17:12:59 main.py[line:96] ERROR 数据执行失败:(1146, "Table 'task.item' doesn't exist")
2018-06-14 17:12:59 main.py[line:96] ERROR 数据执行失败:(1146, "Table 'task.department' doesn't exist")
2018-06-14 17:21:46 main.py[line:96] ERROR 数据执行失败:(1146, "Table 'task.item' doesn't exist")
2018-06-14 17:21:46 main.py[line:96] ERROR 数据执行失败:(1146, "Table 'task.department' doesn't exist")
2018-06-16 15:21:39 main.py[line:96] ERROR 数据执行失败:%d format: a number is required, not str
2018-06-16 15:23:36 main.py[line:96] ERROR 数据执行失败:%d format: a number is required, not str
2018-06-16 15:24:34 main.py[line:96] ERROR 数据执行失败:%d format: a number is required, not str
2018-06-16 23:01:48 main.py[line:96] ERROR 数据执行失败:not enough arguments for format string
2018-06-16 23:06:08 main.py[line:96] ERROR 数据执行失败:not enough arguments for format string
2018-06-16 23:59:42 main.py[line:96] ERROR 数据执行失败:'long' object is not iterable
2018-06-17 00:03:58 main.py[line:96] ERROR 数据执行失败:'long' object is not iterable
2018-06-17 00:04:19 main.py[line:96] ERROR 数据执行失败:'long' object is not iterable
2018-06-17 00:05:20 main.py[line:96] ERROR 数据执行失败:'long' object is not iterable
2018-06-17 00:06:02 main.py[line:96] ERROR 数据执行失败:'long' object is not iterable
2018-06-17 17:59:11 main.py[line:96] ERROR 数据执行失败:(1146, "Table 'task.item' doesn't exist")
2018-06-17 17:59:11 main.py[line:96] ERROR 数据执行失败:(1146, "Table 'task.department' doesn't exist")
2018-06-17 17:59:45 main.py[line:96] ERROR 数据执行失败:(1146, "Table 'task.item' doesn't exist")
2018-06-17 17:59:45 main.py[line:96] ERROR 数据执行失败:(1146, "Table 'task.department' doesn't exist")
2018-06-17 23:37:41 main.py[line:96] ERROR 数据执行失败:not all arguments converted during string formatting
2018-06-17 23:37:43 main.py[line:96] ERROR 数据执行失败:not all arguments converted during string formatting
2018-06-17 23:42:31 main.py[line:96] ERROR 数据执行失败:not all arguments converted during string formatting
2018-06-17 23:44:47 main.py[line:96] ERROR 数据执行失败:not all arguments converted during string formatting
2018-06-17 23:44:50 main.py[line:96] ERROR 数据执行失败:not all arguments converted during string formatting
2018-06-17 23:45:12 main.py[line:96] ERROR 数据执行失败:not all arguments converted during string formatting
2018-06-17 23:45:15 main.py[line:96] ERROR 数据执行失败:not all arguments converted during string formatting
2018-06-17 23:45:43 main.py[line:96] ERROR 数据执行失败:not all arguments converted during string formatting
2018-06-17 23:45:45 main.py[line:96] ERROR 数据执行失败:not all arguments converted during string formatting
2018-06-19 17:45:07 main.py[line:96] ERROR 数据执行失败:(1146, "Table 'task.item' doesn't exist")
2018-06-19 17:45:07 main.py[line:96] ERROR 数据执行失败:(1146, "Table 'task.department' doesn't exist")
2018-06-19 17:45:44 main.py[line:96] ERROR 数据执行失败:(1146, "Table 'task.item' doesn't exist")
2018-06-19 17:45:44 main.py[line:96] ERROR 数据执行失败:(1146, "Table 'task.department' doesn't exist")
2018-06-19 17:51:54 main.py[line:71] ERROR 数据写入失败:(1451, 'Cannot delete or update a parent row: a foreign key constraint fails (`task`.`scorelist`, CONSTRAINT `scorelist_ibfk_1` FOREIGN KEY (`inputid`) REFERENCES `user` (`id`) ON DELETE NO ACTION ON UPDATE NO ACTION)')
2018-06-19 17:51:56 main.py[line:71] ERROR 数据写入失败:(1451, 'Cannot delete or update a parent row: a foreign key constraint fails (`task`.`scorelist`, CONSTRAINT `scorelist_ibfk_1` FOREIGN KEY (`inputid`) REFERENCES `user` (`id`) ON DELETE NO ACTION ON UPDATE NO ACTION)')
2018-06-19 17:51:57 main.py[line:71] ERROR 数据写入失败:(1451, 'Cannot delete or update a parent row: a foreign key constraint fails (`task`.`scorelist`, CONSTRAINT `scorelist_ibfk_1` FOREIGN KEY (`inputid`) REFERENCES `user` (`id`) ON DELETE NO ACTION ON UPDATE NO ACTION)')
2018-06-19 17:51:59 main.py[line:71] ERROR 数据写入失败:(1451, 'Cannot delete or update a parent row: a foreign key constraint fails (`task`.`scorelist`, CONSTRAINT `scorelist_ibfk_1` FOREIGN KEY (`inputid`) REFERENCES `user` (`id`) ON DELETE NO ACTION ON UPDATE NO ACTION)')
2018-06-19 17:52:12 main.py[line:71] ERROR 数据写入失败:(1451, 'Cannot delete or update a parent row: a foreign key constraint fails (`task`.`scorelist`, CONSTRAINT `scorelist_ibfk_1` FOREIGN KEY (`inputid`) REFERENCES `user` (`id`) ON DELETE NO ACTION ON UPDATE NO ACTION)')
2018-06-19 17:52:12 main.py[line:71] ERROR 数据写入失败:(1451, 'Cannot delete or update a parent row: a foreign key constraint fails (`task`.`scorelist`, CONSTRAINT `scorelist_ibfk_1` FOREIGN KEY (`inputid`) REFERENCES `user` (`id`) ON DELETE NO ACTION ON UPDATE NO ACTION)')
2018-06-19 17:52:13 main.py[line:71] ERROR 数据写入失败:(1451, 'Cannot delete or update a parent row: a foreign key constraint fails (`task`.`scorelist`, CONSTRAINT `scorelist_ibfk_1` FOREIGN KEY (`inputid`) REFERENCES `user` (`id`) ON DELETE NO ACTION ON UPDATE NO ACTION)')
2018-06-19 17:52:13 main.py[line:71] ERROR 数据写入失败:(1451, 'Cannot delete or update a parent row: a foreign key constraint fails (`task`.`scorelist`, CONSTRAINT `scorelist_ibfk_1` FOREIGN KEY (`inputid`) REFERENCES `user` (`id`) ON DELETE NO ACTION ON UPDATE NO ACTION)')
2018-06-19 17:52:13 main.py[line:71] ERROR 数据写入失败:(1451, 'Cannot delete or update a parent row: a foreign key constraint fails (`task`.`scorelist`, CONSTRAINT `scorelist_ibfk_1` FOREIGN KEY (`inputid`) REFERENCES `user` (`id`) ON DELETE NO ACTION ON UPDATE NO ACTION)')
2018-06-19 17:52:13 main.py[line:71] ERROR 数据写入失败:(1451, 'Cannot delete or update a parent row: a foreign key constraint fails (`task`.`scorelist`, CONSTRAINT `scorelist_ibfk_1` FOREIGN KEY (`inputid`) REFERENCES `user` (`id`) ON DELETE NO ACTION ON UPDATE NO ACTION)')
2018-06-19 17:52:13 main.py[line:71] ERROR 数据写入失败:(1451, 'Cannot delete or update a parent row: a foreign key constraint fails (`task`.`scorelist`, CONSTRAINT `scorelist_ibfk_1` FOREIGN KEY (`inputid`) REFERENCES `user` (`id`) ON DELETE NO ACTION ON UPDATE NO ACTION)')
2018-06-19 17:52:13 main.py[line:71] ERROR 数据写入失败:(1451, 'Cannot delete or update a parent row: a foreign key constraint fails (`task`.`scorelist`, CONSTRAINT `scorelist_ibfk_1` FOREIGN KEY (`inputid`) REFERENCES `user` (`id`) ON DELETE NO ACTION ON UPDATE NO ACTION)')
2018-06-19 17:52:14 main.py[line:71] ERROR 数据写入失败:(1451, 'Cannot delete or update a parent row: a foreign key constraint fails (`task`.`scorelist`, CONSTRAINT `scorelist_ibfk_1` FOREIGN KEY (`inputid`) REFERENCES `user` (`id`) ON DELETE NO ACTION ON UPDATE NO ACTION)')
2018-06-19 17:52:14 main.py[line:71] ERROR 数据写入失败:(1451, 'Cannot delete or update a parent row: a foreign key constraint fails (`task`.`scorelist`, CONSTRAINT `scorelist_ibfk_1` FOREIGN KEY (`inputid`) REFERENCES `user` (`id`) ON DELETE NO ACTION ON UPDATE NO ACTION)')
2018-06-19 23:18:21 main.py[line:96] ERROR 数据执行失败:(1146, "Table 'task.item' doesn't exist")
2018-06-19 23:18:21 main.py[line:96] ERROR 数据执行失败:(1146, "Table 'task.department' doesn't exist")
2018-06-20 00:02:43 main.py[line:96] ERROR 数据执行失败:(1064, 'You have an error in your SQL syntax; check the manual that corresponds to your MySQL server version for the right syntax to use near \'\'MAX(date)\': "\'2018-06-22\'"}\' at line 6')
